Workbook

Sheet 万相台
A1: Date 时间 | B1: Cost 花费 | C1: IMP 观看量 | D1: Click 点击 | E1: Order 订单 | F1: Sales 销量 | G1: ShoppingCart 加入购物车 | H1: Bookmark-Product 宝贝收藏 | I1: CTR 点击率 | J1: CPC 点击成本 | K1: CPM 拉新成本 | L1: ROI 投资回报率 | M1: CVR 点击转化率
A2: 45161 | B2: 100 | C2: 3753 | D2: 62 | E2: 0 | F2: 0 | G2: 0 | H2: 0 | I2: =D2/C2 -> 0.016520117 | J2: =B2/D2 -> 1.6129032 | K2: =B2/C2*1000 -> 26.64535 | L2: =F2/B2 -> 0 | M2: =E2/D2 -> 0
A3: 45162 | B3: 100 | C3: 427 | D3: 57 | E3: 0 | F3: 0 | G3: 0 | H3: 0 | I3: =D3/C3 -> 0.13348946 | J3: =B3/D3 -> 1.754386 | K3: =B3/C3*1000 -> 234.19204 | L3: =F3/B3 -> 0 | M3: =E3/D3 -> 0
A4: 45163 | B4: 100 | C4: 369 | D4: 83 | E4: 0 | F4: 0 | G4: 1 | H4: 1 | I4: =D4/C4 -> 0.22493225 | J4: =B4/D4 -> 1.2048193 | K4: =B4/C4*1000 -> 271.00271 | L4: =F4/B4 -> 0 | M4: =E4/D4 -> 0
A5: 45164 | B5: 98.9 | C5: 1022 | D5: 57 | E5: 0 | F5: 0 | G5: 2 | H5: 1 | I5: =D5/C5 -> 0.055772994 | J5: =B5/D5 -> 1.7350877 | K5: =B5/C5*1000 -> 96.771037 | L5: =F5/B5 -> 0 | M5: =E5/D5 -> 0
A6: 45165 | B6: 99.86 | C6: 1470 | D6: 113 | E6: 0 | F6: 0 | G6: 6 | H6: 2 | I6: =D6/C6 -> 0.076870748 | J6: =B6/D6 -> 0.88371681 | K6: =B6/C6*1000 -> 67.931973 | L6: =F6/B6 -> 0 | M6: =E6/D6 -> 0
A7: 45166 | B7: 99.85 | C7: 836 | D7: 70 | E7: 0 | F7: 0 | G7: 2 | H7: 1 | I7: =D7/C7 -> 0.083732057 | J7: =B7/D7 -> 1.4264286 | K7: =B7/C7*1000 -> 119.4378 | L7: =F7/B7 -> 0 | M7: =E7/D7 -> 0
A8: 45167 | B8: =99.55+16.15 -> 115.7 | C8: =1117+564 -> 1681 | D8: =89+6 -> 95 | E8: 0 | F8: 0 | G8: 4 | H8: 1 | I8: =D8/C8 -> 0.05651398 | J8: =B8/D8 -> 1.2178947 | K8: =B8/C8*1000 -> 68.828079 | L8: =F8/B8 -> 0 | M8: =E8/D8 -> 0
A9: 45168 | B9: =100+49.99 -> 149.99 | C9: =1513+20522 -> 22035 | D9: =89+128 -> 217 | E9: 0 | F9: 0 | G9: 4 | H9: 4 | I9: =D9/C9 -> 0.0098479691 | J9: =B9/D9 -> 0.69119816 | K9: =B9/C9*1000 -> 6.8068981 | L9: =F9/B9 -> 0 | M9: =E9/D9 -> 0
A10: 45169 | B10: =100+49.73 -> 149.73 | C10: =1449+63352 -> 64801 | D10: =86+286 -> 372 | E10: 0 | F10: 0 | G10: =1+2 -> 3 | H10: =1+1 -> 2 | I10: =D10/C10 -> 0.0057406522 | J10: =B10/D10 -> 0.4025 | K10: =B10/C10*1000 -> 2.3106125 | L10: =F10/B10 -> 0 | M10: =E10/D10 -> 0
A11: 45170 | B11: =100+48.46 -> 148.46 | C11: =1505+88321 -> 89826 | D11: =87+289 -> 376 | E11: 0 | F11: 0 | G11: 3 | H11: 1 | I11: =D11/C11 -> 0.0041858705 | J11: =B11/D11 -> 0.39484043 | K11: =B11/C11*1000 -> 1.6527509 | L11: =F11/B11 -> 0 | M11: =E11/D11 -> 0
A12: 45171 | B12: =98.92+48.89 -> 147.81 | C12: =2061+80573 -> 82634 | D12: =115+446 -> 561 | E12: 0 | F12: 0 | G12: 2 | H12: 3 | I12: =D12/C12 -> 0.0067889731 | J12: =B12/D12 -> 0.26347594 | K12: =B12/C12*1000 -> 1.788731 | L12: =F12/B12 -> 0 | M12: =E12/D12 -> 0
A13: 45172 | B13: =99.58+49.56 -> 149.14 | C13: =1772+75598 -> 77370 | D13: =109+485 -> 594 | E13: 0 | F13: 0 | G13: 3 | H13: 2 | I13: =D13/C13 -> 0.0076773943 | J13: =B13/D13 -> 0.25107744 | K13: =B13/C13*1000 -> 1.9276205 | L13: =F13/B13 -> 0 | M13: =E13/D13 -> 0
A14: 45173 | B14: =100+49.58 -> 149.58 | C14: =1643+38704 -> 40347 | D14: =95+278 -> 373 | E14: 0 | F14: 0 | G14: 5 | H14: 7 | I14: =D14/C14 -> 0.0092448013 | J14: =B14/D14 -> 0.40101877 | K14: =B14/C14*1000 -> 3.7073388 | L14: =F14/B14 -> 0 | M14: =E14/D14 -> 0
A15: 45174 | B15: =100+48.53 -> 148.53 | C15: =1870+26465 -> 28335 | D15: =104+190 -> 294 | E15: 0 | F15: 0 | G15: 6 | H15: 4 | I15: =D15/C15 -> 0.01037586 | J15: =B15/D15 -> 0.50520408 | K15: =B15/C15*1000 -> 5.2419269 | L15: =F15/B15 -> 0 | M15: =E15/D15 -> 0
A16: 45175 | B16: =98.92+48.82 -> 147.74 | C16: =1920+10265 -> 12185 | D16: =85+98 -> 183 | E16: 0 | F16: 0 | G16: 2 | H16: 7 | I16: =D16/C16 -> 0.015018465 | J16: =B16/D16 -> 0.8073224 | K16: =B16/C16*1000 -> 12.124744 | L16: =F16/B16 -> 0 | M16: =E16/D16 -> 0
A17: 45176 | B17: =99.92+49.69 -> 149.61 | C17: =2272+9284 -> 11556 | D17: =116+110 -> 226 | E17: 0 | F17: 0 | G17: 5 | H17: 5 | I17: =D17/C17 -> 0.01955694 | J17: =B17/D17 -> 0.66199115 | K17: =B17/C17*1000 -> 12.946521 | L17: =F17/B17 -> 0 | M17: =E17/D17 -> 0
A18: 45177 | B18: 148.75 | C18: 16076 | D18: 255 | E18: 0 | F18: 0 | G18: 7 | H18: 9 | I18: =D18/C18 -> 0.015862155 | J18: =B18/D18 -> 0.58333333 | K18: =B18/C18*1000 -> 9.2529236 | L18: =F18/B18 -> 0 | M18: =E18/D18 -> 0
A19: 45178 | B19: 149.28 | C19: 17407 | D19: 387 | E19: 0 | F19: 0 | G19: 5 | H19: 3 | I19: =D19/C19 -> 0.022232435 | J19: =B19/D19 -> 0.38573643 | K19: =B19/C19*1000 -> 8.5758603 | L19: =F19/B19 -> 0 | M19: =E19/D19 -> 0
A20: 45179 | B20: 147.9 | C20: 17213 | D20: 428 | E20: 0 | F20: 0 | G20: 7 | H20: 9 | I20: =D20/C20 -> 0.024864928 | J20: =B20/D20 -> 0.34556075 | K20: =B20/C20*1000 -> 8.592343 | L20: =F20/B20 -> 0 | M20: =E20/D20 -> 0
A21: 45180 | B21: 149.62 | C21: =3506+13717 -> 17223 | D21: =115+228 -> 343 | E21: 0 | F21: 0 | G21: 8 | H21: 9 | I21: =D21/C21 -> 0.01991523 | J21: =B21/D21 -> 0.43620991 | K21: =B21/C21*1000 -> 8.6872206 | L21: =F21/B21 -> 0 | M21: =E21/D21 -> 0
A22: 45181 | B22: 206 | C22: 11164 | D22: 187 | E22: 0 | F22: 0 | G22: 5 | H22: 10 | I22: =D22/C22 -> 0.016750269 | J22: =B22/D22 -> 1.1016043 | K22: =B22/C22*1000 -> 18.452168 | L22: =F22/B22 -> 0 | M22: =E22/D22 -> 0
A23: 45182 | B23: =99.31+46.06 -> 145.37 | C23: =14620+3933 -> 18553 | D23: =116+265 -> 381 | E23: 0 | F23: 0 | G23: 2 | H23: 5 | I23: =D23/C23 -> 0.020535762 | J23: =B23/D23 -> 0.38154856 | K23: =B23/C23*1000 -> 7.8353905 | L23: =F23/B23 -> 0 | M23: =E23/D23 -> 0
A24: 45183 | B24: 142.38 | C24: =3416+4903 -> 8319 | D24: =206+41 -> 247 | E24: 0 | F24: 0 | G24: 0 | H24: 1 | I24: =D24/C24 -> 0.029691069 | J24: =B24/D24 -> 0.57643725 | K24: =B24/C24*1000 -> 17.115038 | L24: =F24/B24 -> 0 | M24: =E24/D24 -> 0
A25: 45184 | B25: =43.62+99.83 -> 143.45 | C25: =6174+1749 -> 7923 | D25: =45+124 -> 169 | E25: 0 | F25: 0 | G25: 6 | H25: 0 | I25: =D25/C25 -> 0.021330304 | J25: =B25/D25 -> 0.84881657 | K25: =B25/C25*1000 -> 18.105516 | L25: =F25/B25 -> 0 | M25: =E25/D25 -> 0
A26: 45185 | B26: =98.94+49.95 -> 148.89 | C26: =3872+1803 -> 5675 | D26: =40+124 -> 164 | E26: 0 | F26: 0 | G26: 2 | H26: 1 | I26: =D26/C26 -> 0.028898678 | J26: =B26/D26 -> 0.90786585 | K26: =B26/C26*1000 -> 26.236123 | L26: =F26/B26 -> 0 | M26: =E26/D26 -> 0
A27: 45186 | B27: =99.76+43.62 -> 143.38 | C27: =4798+2062 -> 6860 | D27: =40+159 -> 199 | E27: 0 | F27: 0 | G27: 0 | H27: 0 | I27: =D27/C27 -> 0.029008746 | J27: =B27/D27 -> 0.72050251 | K27: =B27/C27*1000 -> 20.900875 | L27: =F27/B27 -> 0 | M27: =E27/D27 -> 0
A28: 45187 | B28: 141.52 | C28: =2252+2877 -> 5129 | D28: =132+49 -> 181 | E28: 0 | F28: 0 | G28: 2 | H28: 1 | I28: =D28/C28 -> 0.03528953 | J28: =B28/D28 -> 0.78187845 | K28: =B28/C28*1000 -> 27.592123 | L28: =F28/B28 -> 0 | M28: =E28/D28 -> 0
A29: 45188 | B29: =99.11+48.96 -> 148.07 | C29: =3065+2559 -> 5624 | D29: =31+158 -> 189 | E29: 0 | F29: 0 | G29: 0 | H29: 1 | I29: =D29/C29 -> 0.033605974 | J29: =B29/D29 -> 0.78343915 | K29: =B29/C29*1000 -> 26.328236 | L29: =F29/B29 -> 0 | M29: =E29/D29 -> 0
A30: 45189 | B30: 313 | C30: =3484+630 -> 4114 | D30: 175 | E30: 0 | F30: 0 | G30: 0 | H30: 0 | I30: =D30/C30 -> 0.042537676 | J30: =B30/D30 -> 1.7885714 | K30: =B30/C30*1000 -> 76.081672 | L30: =F30/B30 -> 0 | M30: =E30/D30 -> 0
A31: 45190 | B31: =51.78+88.78+97.76+95.17+93.5+22.8+100+100 -> 649.79 | C31: =63+263+450+731+147+34+283+3735 -> 5706 | D31: 205 | E31: 0 | F31: 0 | G31: 1 | H31: 1 | I31: =D31/C31 -> 0.035927094 | J31: =B31/D31 -> 3.1697073 | K31: =B31/C31*1000 -> 113.87837 | L31: =F31/B31 -> 0 | M31: =E31/D31 -> 0
A32: 45191 | B32: 100 | C32: 3966 | D32: 253 | E32: 0 | F32: 0 | G32: 1 | H32: 3 | I32: =D32/C32 -> 0.063792234 | J32: =B32/D32 -> 0.39525692 | K32: =B32/C32*1000 -> 25.214322 | L32: =F32/B32 -> 0 | M32: =E32/D32 -> 0
A33: 45192 | B33: 129.05 | C33: 5201 | D33: 193 | E33: 0 | F33: 0 | G33: 2 | H33: 1 | I33: =D33/C33 -> 0.037108248 | J33: =B33/D33 -> 0.66865285 | K33: =B33/C33*1000 -> 24.812536 | L33: =F33/B33 -> 0 | M33: =E33/D33 -> 0
A34: 45193 | B34: 146.71 | C34: 5251 | D34: 424 | E34: 0 | F34: 0 | G34: 1 | H34: 4 | I34: =D34/C34 -> 0.080746524 | J34: =B34/D34 -> 0.34601415 | K34: =B34/C34*1000 -> 27.93944 | L34: =F34/B34 -> 0 | M34: =E34/D34 -> 0
A35: 45194 | B35: =99.7+100+100+91.89+99.38+100+49.71 -> 640.68 | C35: =50434+2967+2825 -> 56226 | D35: =229+198+60 -> 487 | E35: 1 | F35: 1 | G35: 3 | H35: 0 | I35: =D35/C35 -> 0.0086614733 | J35: =B35/D35 -> 1.3155647 | K35: =B35/C35*1000 -> 11.394728 | L35: =F35/B35 -> 0.0015608416 | M35: =E35/D35 -> 0.0020533881
A36: 45195 | B36: =49.8+100 -> 149.8 | C36: =1818+61479 -> 63297 | D36: =225+121 -> 346 | E36: 0 | F36: 0 | G36: 3 | H36: 3 | I36: =D36/C36 -> 0.0054662938 | J36: =B36/D36 -> 0.43294798 | K36: =B36/C36*1000 -> 2.3666209 | L36: =F36/B36 -> 0 | M36: =E36/D36 -> 0
A37: 45196 | B37: =100+49.82 -> 149.82 | C37: 52701 | D37: =190+105 -> 295 | E37: 2 | F37: 3400 | G37: 2 | H37: 1 | I37: =D37/C37 -> 0.0055976167 | J37: =B37/D37 -> 0.50786441 | K37: =B37/C37*1000 -> 2.8428303 | L37: =F37/B37 -> 22.693899 | M37: =E37/D37 -> 0.006779661
A38: 45197 | B38: =483.78+99.82+49.58 -> 633.18 | C38: =44226+1495+7689 -> 53410 | D38: =225+108+195 -> 528 | E38: 0 | F38: 0 | G38: 7 | H38: 1 | I38: =D38/C38 -> 0.0098857892 | J38: =B38/D38 -> 1.1992045 | K38: =B38/C38*1000 -> 11.855083 | L38: =F38/B38 -> 0 | M38: =E38/D38 -> 0
A39: 45198 | B39: =100+49.36 -> 149.36 | C39: 18104 | D39: =72+130 -> 202 | E39: 3 | F39: 2969 | G39: 13 | H39: 1 | I39: =D39/C39 -> 0.011157755 | J39: =B39/D39 -> 0.73940594 | K39: =B39/C39*1000 -> 8.2501105 | L39: =F39/B39 -> 19.878147 | M39: =E39/D39 -> 0.014851485
A40: 45199 | B40: =99.47+49.69 -> 149.16 | C40: =1442+7575 -> 9017 | D40: =64+99 -> 163 | E40: 1 | F40: 9.9 | G40: 12 | H40: 3 | I40: =D40/C40 -> 0.018076966 | J40: =B40/D40 -> 0.91509202 | K40: =B40/C40*1000 -> 16.542087 | L40: =F40/B40 -> 0.066371681 | M40: =E40/D40 -> 0.0061349693
...
